<?xml version="1.0" encoding="utf-8"?>
<!-- This URDF was automatically created by SolidWorks to URDF Exporter! Originally created by Stephen Brawner (brawner@gmail.com) 
     Commit Version: 1.6.0-4-g7f85cfe  Build Version: 1.6.7995.38578
     For more information, please see http://wiki.ros.org/sw_urdf_exporter -->
<robot
  name="bip4_des">
  <mujoco>
    <compiler
        meshdir="meshes/"
        balanceinertia="true"
        discardvisual="false" />
  </mujoco>
  <link
    name="base_link">
    <inertial>
      <origin
        xyz="-0.066232 0.00036919 2.7147E-06"
        rpy="0 0 0" />
      <mass
        value="5.5946" />
      <inertia
        ixx="0.0047064"
        ixy="-1.6682E-05"
        ixz="1.0516E-06"
        iyy="0.0053372"
        iyz="-3.4671E-06"
        izz="0.0046558" />
    </inertial>
    <visual>
      <origin
        xyz="0 0 0"
        rpy="0 0 0" />
      <geometry>
        <mesh
          filename="package://bip4_des/meshes/base_link.STL" />
      </geometry>
      <material
        name="">
        <color
          rgba="0.75294 0.75294 0.75294 1" />
      </material>
    </visual>
    <collision>
      <origin
        xyz="0 0 0"
        rpy="0 0 0" />
      <geometry>
        <mesh
          filename="package://bip4_des/meshes/base_link.STL" />
      </geometry>
    </collision>
  </link>
  <link
    name="l_hip_roll_Link">
    <inertial>
      <origin
        xyz="0.007702 8.0599E-05 -0.0041394"
        rpy="0 0 0" />
      <mass
        value="1.8362" />
      <inertia
        ixx="0.0013515"
        ixy="-1.3161E-06"
        ixz="7.5975E-07"
        iyy="0.0014774"
        iyz="-6.5562E-06"
        izz="0.0013748" />
    </inertial>
    <visual>
      <origin
        xyz="0 0 0"
        rpy="0 0 0" />
      <geometry>
        <mesh
          filename="package://bip4_des/meshes/l_hip_roll_Link.STL" />
      </geometry>
      <material
        name="">
        <color
          rgba="0.75294 0.75294 0.75294 1" />
      </material>
    </visual>
    <collision>
      <origin
        xyz="0 0 0"
        rpy="0 0 0" />
      <geometry>
        <mesh
          filename="package://bip4_des/meshes/l_hip_roll_Link.STL" />
      </geometry>
    </collision>
  </link>
  <joint
    name="J_hip_l_roll"
    type="revolute">
    <origin
      xyz="0 0.085 0"
      rpy="0 0 0" />
    <parent
      link="base_link" />
    <child
      link="l_hip_roll_Link" />
    <axis
      xyz="1 0 0" />
    <limit
      lower="-0.05"
      upper="1.0"
      effort="0"
      velocity="0" />
  </joint>
  <link
    name="l_hip_yaw_Link">
    <inertial>
      <origin
        xyz="-4.3368E-18 0.0047249 -0.032157"
        rpy="0 0 0" />
      <mass
        value="0.18597" />
      <inertia
        ixx="0.00054536"
        ixy="2.2098E-19"
        ixz="-1.2488E-19"
        iyy="0.00028776"
        iyz="5.5703E-05"
        izz="0.00045609" />
    </inertial>
    <visual>
      <origin
        xyz="0 0 0"
        rpy="0 0 0" />
      <geometry>
        <mesh
          filename="package://bip4_des/meshes/l_hip_yaw_Link.STL" />
      </geometry>
      <material
        name="">
        <color
          rgba="0.75294 0.75294 0.75294 1" />
      </material>
    </visual>
    <collision>
      <origin
        xyz="0 0 0"
        rpy="0 0 0" />
      <geometry>
        <mesh
          filename="package://bip4_des/meshes/l_hip_yaw_Link.STL" />
      </geometry>
    </collision>
  </link>
  <joint
    name="J_hip_l_yaw"
    type="revolute">
    <origin
      xyz="0.00755 0 -0.041"
      rpy="0 0 0" />
    <parent
      link="l_hip_roll_Link" />
    <child
      link="l_hip_yaw_Link" />
    <axis
      xyz="0 0 1" />
    <limit
      lower="-0.8"
      upper="0.8"
      effort="0"
      velocity="0" />
  </joint>
  <link
    name="l_hip_pitch_Link">
    <inertial>
      <origin
        xyz="0.00016671 0.0072394 -0.066453"
        rpy="0 0 0" />
      <mass
        value="10.605" />
      <inertia
        ixx="0.013974"
        ixy="-4.6354E-06"
        ixz="3.5128E-06"
        iyy="0.017107"
        iyz="-4.3453E-06"
        izz="0.011931" />
    </inertial>
    <visual>
      <origin
        xyz="0 0 0"
        rpy="0 0 0" />
      <geometry>
        <mesh
          filename="package://bip4_des/meshes/l_hip_pitch_Link.STL" />
      </geometry>
      <material
        name="">
        <color
          rgba="0.75294 0.75294 0.75294 1" />
      </material>
    </visual>
    <collision>
      <origin
        xyz="0 0 0"
        rpy="0 0 0" />
      <geometry>
        <mesh
          filename="package://bip4_des/meshes/l_hip_pitch_Link.STL" />
      </geometry>
    </collision>
  </link>
  <joint
    name="J_hip_l_pitch"
    type="revolute">
    <origin
      xyz="0 0 -0.071"
      rpy="0 0 0" />
    <parent
      link="l_hip_yaw_Link" />
    <child
      link="l_hip_pitch_Link" />
    <axis
      xyz="0 1 0" />
    <limit
      lower="-1.5"
      upper="1.5"
      effort="0"
      velocity="0" />
  </joint>
  <link
    name="l_knee_Link">
    <inertial>
      <origin
        xyz="-0.0080643 0.0026112 -0.13064"
        rpy="0 0 0" />
      <mass
        value="3.4252" />
      <inertia
        ixx="0.0068071"
        ixy="4.0329E-06"
        ixz="-0.00032143"
        iyy="0.0067824"
        iyz="6.7283E-06"
        izz="0.0025764" />
    </inertial>
    <visual>
      <origin
        xyz="0 0 0"
        rpy="0 0 0" />
      <geometry>
        <mesh
          filename="package://bip4_des/meshes/l_knee_Link.STL" />
      </geometry>
      <material
        name="">
        <color
          rgba="0.75294 0.75294 0.75294 1" />
      </material>
    </visual>
    <collision>
      <origin
        xyz="0 0 0"
        rpy="0 0 0" />
      <geometry>
        <mesh
          filename="package://bip4_des/meshes/l_knee_Link.STL" />
      </geometry>
    </collision>
  </link>
  <joint
    name="J_knee_l_pitch"
    type="revolute">
    <origin
      xyz="0 0 -0.3"
      rpy="0 0 0" />
    <parent
      link="l_hip_pitch_Link" />
    <child
      link="l_knee_Link" />
    <axis
      xyz="0 1 0" />
    <limit
      lower="-0.1"
      upper="1.7"
      effort="0"
      velocity="0" />
  </joint>
  <link
    name="l_ankle_Link">
    <inertial>
      <origin
        xyz="0.025627 0.002347 -0.031389"
        rpy="0 0 0" />
      <mass
        value="0.3255" />
      <inertia
        ixx="7.343E-05"
        ixy="-1.3319E-06"
        ixz="4.7624E-05"
        iyy="0.00067827"
        iyz="1.9233E-07"
        izz="0.00069239" />
    </inertial>
    <visual>
      <origin
        xyz="0 0 0"
        rpy="0 0 0" />
      <geometry>
        <mesh
          filename="package://bip4_des/meshes/l_ankle_Link.STL" />
      </geometry>
      <material
        name="">
        <color
          rgba="0.75294 0.75294 0.75294 1" />
      </material>
    </visual>
    <collision>
      <origin
        xyz="0 0 0"
        rpy="0 0 0" />
      <geometry>
        <mesh
          filename="package://bip4_des/meshes/l_ankle_Link.STL" />
      </geometry>
    </collision>
  </link>
  <joint
    name="J_ankle_l_pitch"
    type="revolute">
    <origin
      xyz="0 0 -0.4"
      rpy="0 0 0" />
    <parent
      link="l_knee_Link" />
    <child
      link="l_ankle_Link" />
    <axis
      xyz="0 1 0" />
    <limit
      lower="-0.6"
      upper="0.6"
      effort="0"
      velocity="0" />
  </joint>
  <link
    name="r_hip_roll_Link">
    <inertial>
      <origin
        xyz="0.007702 8.0599E-05 -0.0041394"
        rpy="0 0 0" />
      <mass
        value="1.8362" />
      <inertia
        ixx="0.0013515"
        ixy="-1.3161E-06"
        ixz="7.5975E-07"
        iyy="0.0014774"
        iyz="-6.5562E-06"
        izz="0.0013748" />
    </inertial>
    <visual>
      <origin
        xyz="0 0 0"
        rpy="0 0 0" />
      <geometry>
        <mesh
          filename="package://bip4_des/meshes/r_hip_roll_Link.STL" />
      </geometry>
      <material
        name="">
        <color
          rgba="0.75294 0.75294 0.75294 1" />
      </material>
    </visual>
    <collision>
      <origin
        xyz="0 0 0"
        rpy="0 0 0" />
      <geometry>
        <mesh
          filename="package://bip4_des/meshes/r_hip_roll_Link.STL" />
      </geometry>
    </collision>
  </link>
  <joint
    name="J_hip_r_roll"
    type="revolute">
    <origin
      xyz="0 -0.085 0"
      rpy="0 0 0" />
    <parent
      link="base_link" />
    <child
      link="r_hip_roll_Link" />
    <axis
      xyz="1 0 0" />
    <limit
      lower="-1.0"
      upper="0.05"
      effort="0"
      velocity="0" />
  </joint>
  <link
    name="r_hip_yaw_Link">
    <inertial>
      <origin
        xyz="2.6888E-17 -0.0047249 -0.032157"
        rpy="0 0 0" />
      <mass
        value="0.18597" />
      <inertia
        ixx="0.00054536"
        ixy="1.1784E-19"
        ixz="1.7991E-21"
        iyy="0.00028776"
        iyz="-5.5703E-05"
        izz="0.00045609" />
    </inertial>
    <visual>
      <origin
        xyz="0 0 0"
        rpy="0 0 0" />
      <geometry>
        <mesh
          filename="package://bip4_des/meshes/r_hip_yaw_Link.STL" />
      </geometry>
      <material
        name="">
        <color
          rgba="0.75294 0.75294 0.75294 1" />
      </material>
    </visual>
    <collision>
      <origin
        xyz="0 0 0"
        rpy="0 0 0" />
      <geometry>
        <mesh
          filename="package://bip4_des/meshes/r_hip_yaw_Link.STL" />
      </geometry>
    </collision>
  </link>
  <joint
    name="J_hip_r_yaw"
    type="revolute">
    <origin
      xyz="0.00755 0 -0.041"
      rpy="0 0 0" />
    <parent
      link="r_hip_roll_Link" />
    <child
      link="r_hip_yaw_Link" />
    <axis
      xyz="0 0 1" />
    <limit
      lower="-0.8"
      upper="0.8"
      effort="0"
      velocity="0" />
  </joint>
  <link
    name="r_hip_pitch_Link">
    <inertial>
      <origin
        xyz="0.00017061 -0.0072483 -0.066599"
        rpy="0 0 0" />
      <mass
        value="10.607" />
      <inertia
        ixx="0.013994"
        ixy="-3.0476E-06"
        ixz="1.7407E-05"
        iyy="0.017107"
        iyz="-3.6747E-06"
        izz="0.011911" />
    </inertial>
    <visual>
      <origin
        xyz="0 0 0"
        rpy="0 0 0" />
      <geometry>
        <mesh
          filename="package://bip4_des/meshes/r_hip_pitch_Link.STL" />
      </geometry>
      <material
        name="">
        <color
          rgba="0.75294 0.75294 0.75294 1" />
      </material>
    </visual>
    <collision>
      <origin
        xyz="0 0 0"
        rpy="0 0 0" />
      <geometry>
        <mesh
          filename="package://bip4_des/meshes/r_hip_pitch_Link.STL" />
      </geometry>
    </collision>
  </link>
  <joint
    name="J_hip_r_pitch"
    type="revolute">
    <origin
      xyz="0 0 -0.071"
      rpy="0 0 0" />
    <parent
      link="r_hip_yaw_Link" />
    <child
      link="r_hip_pitch_Link" />
    <axis
      xyz="0 1 0" />
    <limit
      lower="-1.5"
      upper="1.5"
      effort="0"
      velocity="0" />
  </joint>
  <link
    name="r_knee_Link">
    <inertial>
      <origin
        xyz="-0.0080643 -0.0011888 -0.13064"
        rpy="0 0 0" />
      <mass
        value="3.4252" />
      <inertia
        ixx="0.0068071"
        ixy="4.0329E-06"
        ixz="-0.00032143"
        iyy="0.0067824"
        iyz="6.7283E-06"
        izz="0.0025764" />
    </inertial>
    <visual>
      <origin
        xyz="0 0 0"
        rpy="0 0 0" />
      <geometry>
        <mesh
          filename="package://bip4_des/meshes/r_knee_Link.STL" />
      </geometry>
      <material
        name="">
        <color
          rgba="0.75294 0.75294 0.75294 1" />
      </material>
    </visual>
    <collision>
      <origin
        xyz="0 0 0"
        rpy="0 0 0" />
      <geometry>
        <mesh
          filename="package://bip4_des/meshes/r_knee_Link.STL" />
      </geometry>
    </collision>
  </link>
  <joint
    name="J_knee_r_pitch"
    type="revolute">
    <origin
      xyz="0 0 -0.3"
      rpy="0 0 0" />
    <parent
      link="r_hip_pitch_Link" />
    <child
      link="r_knee_Link" />
    <axis
      xyz="0 1 0" />
    <limit
      lower="-0.1"
      upper="1.7"
      effort="0"
      velocity="0" />
  </joint>
  <link
    name="r_ankle_Link">
    <inertial>
      <origin
        xyz="0.025627 -0.001453 -0.031389"
        rpy="0 0 0" />
      <mass
        value="0.3255" />
      <inertia
        ixx="7.343E-05"
        ixy="-1.3319E-06"
        ixz="4.7624E-05"
        iyy="0.00067827"
        iyz="1.9233E-07"
        izz="0.00069239" />
    </inertial>
    <visual>
      <origin
        xyz="0 0 0"
        rpy="0 0 0" />
      <geometry>
        <mesh
          filename="package://bip4_des/meshes/r_ankle_Link.STL" />
      </geometry>
      <material
        name="">
        <color
          rgba="0.75294 0.75294 0.75294 1" />
      </material>
    </visual>
    <collision>
      <origin
        xyz="0 0 0"
        rpy="0 0 0" />
      <geometry>
        <mesh
          filename="package://bip4_des/meshes/r_ankle_Link.STL" />
      </geometry>
    </collision>
  </link>
  <joint
    name="J_ankle_r_pitch"
    type="revolute">
    <origin
      xyz="0 0 -0.4"
      rpy="0 0 0" />
    <parent
      link="r_knee_Link" />
    <child
      link="r_ankle_Link" />
    <axis
      xyz="0 1 0" />
    <limit
      lower="-0.6"
      upper="0.6"
      effort="0"
      velocity="0" />
  </joint>
  <link
    name="body_Link">
    <inertial>
      <origin
        xyz="-0.020522 5.744E-05 0.13547"
        rpy="0 0 0" />
      <mass
        value="13.408" />
      <inertia
        ixx="0.061764"
        ixy="3.1044E-07"
        ixz="-3.4396E-05"
        iyy="0.045091"
        iyz="-5.3047E-06"
        izz="0.032291" />
    </inertial>
    <visual>
      <origin
        xyz="0 0 0"
        rpy="0 0 0" />
      <geometry>
        <mesh
          filename="package://bip4_des/meshes/body_Link.STL" />
      </geometry>
      <material
        name="">
        <color
          rgba="0.75294 0.75294 0.75294 1" />
      </material>
    </visual>
    <collision>
      <origin
        xyz="0 0 0"
        rpy="0 0 0" />
      <geometry>
        <mesh
          filename="package://bip4_des/meshes/body_Link.STL" />
      </geometry>
    </collision>
  </link>
  <joint
    name="J_waist_yaw"
    type="revolute">
    <origin
      xyz="0 0 0.048"
      rpy="0 0 0" />
    <parent
      link="base_link" />
    <child
      link="body_Link" />
    <axis
      xyz="0 0 1" />
    <limit
      lower="-1.57"
      upper="1.57"
      effort="0"
      velocity="0" />
  </joint>  
</robot>